<?xml version="1.0"?>
<robot name="Rover" xmlns:xacro="http://www.ros.org/wiki/xacro">

  <xacro:include filename="$(find main)/urdf/materials.xacro" />
  <xacro:include filename="$(find main)/urdf/Rover.trans" />
  <xacro:include filename="$(find main)/urdf/Rover.gazebo" />
  <xacro:include filename="$(find main)/urdf/spring.xacro" />
  <!-- <link name="dummy_base_link"></link> -->


  <link name="base_link">
    <inertial>
      <origin xyz="0.06 0.0 0.3" rpy="0 0 -1.57" />
      <mass value="20.0" />
      <inertia ixx="11.367893" iyy="2.895706" izz="13.361019" ixy="0.0" iyz="0.0" ixz="0.0" />
    </inertial>
    <visual>
      <origin xyz="0 0 0" rpy="0 0 1.57" />
      <geometry>
        <mesh filename="file://$(find main)/meshes/base_link.stl" scale="0.001 0.001 0.001" />
      </geometry>
      <material name="_silver" />

    </visual>
    <collision>
      <origin xyz="0 0 0" rpy="0 0 1.57" />
      <geometry>
        <mesh filename="file://$(find main)/meshes/base_link.stl" scale="0.001 0.001 0.001" />
      </geometry>
    </collision>
  </link>

  <link name="fr_wheel_1">
    <xacro:wheel />
  </link>
  <link name="mr_wheel_1">
    <xacro:wheel />
  </link>
  <link name="br_wheel_1">
    <xacro:wheel />
  </link>
  <link name="fl_wheel_1">
    <xacro:left_wheel />
  </link>
  <link name="ml_wheel_1">
    <xacro:left_wheel />
  </link>
  <link name="bl_wheel_1">
    <xacro:left_wheel />
  </link>


  <link name="cam_link_1">
    <visual>
      <origin xyz="0 0 0" rpy="0 0 0" />
      <geometry>
        <cylinder radius="0.01" length="0.2" />
        <!-- <mesh filename="file://$(find main)/meshes/cam_link_1.stl" scale="0.001 0.001 0.001"/> -->
      </geometry>
      <material name="dark" />
    </visual>
  </link>

  <link name="cam_1">
    <visual>
      <origin xyz="0 0 0" rpy="0 0 0" />
      <geometry>
        <box size="0.03 0.1 0.03" />
      </geometry>
      <material name="dark">
      </material>
    </visual>
  </link>

  <link name="rgbd_1">

  </link>

  <gazebo reference="base_link">
    <sensor name="imu" type="imu">
      <always_on>true</always_on>
      <!-- <visualize>true</visualize> -->
      <update_rate>20</update_rate>
      <gz_frame_id>odom</gz_frame_id>
      <child_frame_id>base_link</child_frame_id>
      <topic>imu</topic>
    </sensor>
  </gazebo>

  <gazebo reference="rgbd_1">
    <sensor name="depth_camera" type="depth">
      <always_on>true</always_on>
      <!-- <visualize>true</visualize> -->
      <update_rate>20</update_rate>
      <topic>depth_camera/image</topic>
      <gz_frame_id>rgbd_1</gz_frame_id>
      <camera name="depth_camera">
        <camera_info_topic>depth_camera/camera_info</camera_info_topic>
        <horizontal_fov>1.8</horizontal_fov>
        <image>
          <width>640</width>
          <height>640</height>
        </image>
        <clip>
          <near>0.1</near>
          <far>25</far>
        </clip>
      </camera>
    </sensor>
  </gazebo>

  <gazebo reference="cam_1">
    <sensor name="camera" type="camera">
      <always_on>true</always_on>
      <!-- <visualize>true</visualize> -->
      <update_rate>10</update_rate>
      <topic>camera/image</topic>
      <gz_frame_id>cam_1</gz_frame_id>
      <camera name="camera">
        <camera_info_topic>camera/camera_info</camera_info_topic>
        <horizontal_fov>1.8</horizontal_fov>
        <image>
          <width>640</width>
          <height>640</height>
        </image>
        <clip>
          <near>0.1</near>
          <far>25</far>
        </clip>
      </camera>
    </sensor>
  </gazebo>

  <gazebo reference="base_link">
    <sensor name="gps" type="gps">
      <always_on>true</always_on>
      <update_rate>10</update_rate>
      <visualize>true</visualize>

      <pose>0 0 0 0 0 0</pose>
      <topic>gps</topic>
      <gz_frame_id>base_link</gz_frame_id>
      <!-- <child_frame_id>base_link</child_frame_id> -->
      <gps>
        <position_sensing>
          <horizontal>
            <noise type="gaussian">
              <mean>0.0</mean>
              <stddev>0.0</stddev>
            </noise>
          </horizontal>
          <vertical>
            <noise type="gaussian">
              <mean>0.0</mean>
              <stddev>0.0</stddev>
            </noise>
          </vertical>
        </position_sensing>
      </gps>
      <!-- <plugin name="my_gps_plugin" filename="libgazebo_ros_gps_sensor.so">
    <ros>
      <remapping>~/out:=/gps/fix</remapping>
    </ros>
  </plugin> -->
    </sensor>
  </gazebo>

  <!-- 
<joint name="dummy" type="fixed">
  <origin xyz="0 0 0" rpy="0 0 0"/>
  <parent link="dummy_base_link"/>
  <child link="base_link"/>
</joint> -->


  <joint name="frw_to_body" type="continuous">
    <origin xyz="0.491042 -0.35  0.196191" rpy="0 0 -1.57" />
    <parent link="base_link" />
    <child link="fr_wheel_1" />
    <axis xyz="-1.0 0.0 0.0" />
  </joint>

  <joint name="mrw_to_body" type="continuous">
    <origin xyz="0.051042 -0.35  0.196191" rpy="0 0 -1.57" />
    <parent link="base_link" />
    <child link="mr_wheel_1" />
    <axis xyz="-1.0 0.0 0.0" />
  </joint>

  <joint name="brw_to_body" type="continuous">
    <origin xyz="-0.388958 -0.35  0.196191" rpy="0 0 -1.57" />
    <parent link="base_link" />
    <child link="br_wheel_1" />
    <axis xyz="-1.0 0.0 0.0" />
  </joint>

  <joint name="flw_to_body" type="continuous">
    <origin xyz="0.491042 0.35  0.196191" rpy="0 0 -1.57" />
    <parent link="base_link" />
    <child link="fl_wheel_1" />
    <axis xyz="-1.0 0.0 0.0" />
  </joint>

  <joint name="mlw_to_body" type="continuous">
    <origin xyz="0.051042 0.35  0.196191" rpy="0 0 -1.57" />
    <parent link="base_link" />
    <child link="ml_wheel_1" />
    <axis xyz="-1.0 0.0 0.0" />
  </joint>


  <joint name="blw_to_body" type="continuous">
    <origin xyz="-0.388958 0.35 0.196191" rpy="0 0 -1.57" />
    <parent link="base_link" />
    <child link="bl_wheel_1" />
    <axis xyz="-1.0 0.0 0.0" />
  </joint>


  <joint name="camlink_to_body" type="fixed">
    <origin xyz="-0.5 0.0 0.8" rpy="0 0 0" />
    <parent link="base_link" />
    <child link="cam_link_1" />
  </joint>

  <joint name="cam_to_camlink" type="fixed">
    <origin xyz="0 0 0.1" rpy="0 0.6 0" />
    <parent link="cam_link_1" />
    <child link="cam_1" />
  </joint>

  <joint name="rgbd_to_camlink" type="fixed">
    <origin xyz="0 0 0.1" rpy="0 0.60 0" />
    <parent link="cam_link_1" />
    <child link="rgbd_1" />
  </joint>


</robot>