<sdf version='1.10'>
  <world name='empty'>
    <scene>
      <shadows>false</shadows>
      <ambient>0.400000006 0.400000006 0.400000006 1</ambient>
      <background>0.699999988 0.699999988 0.699999988 1</background>
    </scene>
    <physics name='1ms' type='ignored'>
      <max_step_size>0.001</max_step_size>
      <real_time_factor>1</real_time_factor>
      <real_time_update_rate>25</real_time_update_rate>
    </physics>
    <plugin name='gz::sim::systems::Physics' filename='gz-sim-physics-system'/>
    <plugin name='gz::sim::systems::UserCommands' filename='gz-sim-user-commands-system'/>
    <plugin name='gz::sim::systems::SceneBroadcaster' filename='gz-sim-scene-broadcaster-system'/>
    <plugin name='gz::sim::systems::Sensors' filename='gz-sim-sensors-system'>
      <render_engine>ogre2</render_engine>
    </plugin>
    <plugin name='gz::sim::systems::Contact' filename='gz-sim-contact-system'/>
    <gravity>0 0 -9.8000000000000007</gravity>
    <magnetic_field>5.5644999999999998e-06 2.2875799999999999e-05 -4.2388400000000002e-05</magnetic_field>
    <atmosphere type='adiabatic'/>
    <model name='ground_plane'>
      <static>true</static>
      <link name='link'>
        <collision name='collision'>
          <geometry>
            <plane>
              <normal>0 0 1</normal>
              <size>100 100</size>
            </plane>
          </geometry>
          <surface>
            <friction>
              <ode/>
            </friction>
            <bounce/>
            <contact/>
          </surface>
        </collision>
        <visual name='visual'>
          <geometry>
            <plane>
              <normal>0 0 1</normal>
              <size>100 100</size>
            </plane>
          </geometry>
          <material>
            <ambient>0.800000012 0.800000012 0.800000012 1</ambient>
            <diffuse>0.800000012 0.800000012 0.800000012 1</diffuse>
            <specular>0.800000012 0.800000012 0.800000012 1</specular>
          </material>
        </visual>
        <pose>0 0 0 0 0 0</pose>
        <inertial>
          <pose>0 0 0 0 0 0</pose>
          <mass>1</mass>
          <inertia>
            <ixx>1</ixx>
            <ixy>0</ixy>
            <ixz>0</ixz>
            <iyy>1</iyy>
            <iyz>0</iyz>
            <izz>1</izz>
          </inertia>
        </inertial>
        <enable_wind>false</enable_wind>
      </link>
      <pose>0 0 0 0 0 0</pose>
      <self_collide>false</self_collide>
    </model>
    <model name='my_world_model'>
      <pose>0 0 0 0 0 0</pose>
      <static>true</static>
      <link name='link'>
        <visual name='visual'>
          <geometry>
            <mesh>
              <uri>file:///bmstu/ros2_ws/src/main/models/my_world_model/model:///bmstu/ros2_ws/src/main/models/my_world_model/meshes/World.obj</uri>
              <scale>0.001 0.001 0.001</scale>
            </mesh>
          </geometry>
          <material>
            <ambient>0.800000012 0.800000012 0.800000012 1</ambient>
            <diffuse>0.5 0.300000012 0.200000003 1</diffuse>
            <specular>0.800000012 0.800000012 0.800000012 1</specular>
          </material>
        </visual>
        <collision name='collision'>
          <geometry>
            <mesh>
              <uri>file:///bmstu/ros2_ws/src/main/models/my_world_model/model:///bmstu/ros2_ws/src/main/models/my_world_model/meshes/World.obj</uri>
              <scale>0.001 0.001 0.001</scale>
            </mesh>
          </geometry>
        </collision>
        <pose>0 0 0 0 0 0</pose>
        <inertial>
          <pose>0 0 0 0 0 0</pose>
          <mass>1</mass>
          <inertia>
            <ixx>1</ixx>
            <ixy>0</ixy>
            <ixz>0</ixz>
            <iyy>1</iyy>
            <iyz>0</iyz>
            <izz>1</izz>
          </inertia>
        </inertial>
        <enable_wind>false</enable_wind>
      </link>
      <self_collide>false</self_collide>
    </model>
    <model name='my_bot'>
      <link name='dummy_base_link'>
        <inertial>
          <pose>0.00058773672774280498 -0.025746338357139961 0.34092177392337392 0 0 0</pose>
          <mass>119.1009454116661</mass>
          <inertia>
            <ixx>2.8961803659257028</ixx>
            <ixy>-0.0085488703522872619</ixy>
            <ixz>0.108554488444221</ixz>
            <iyy>11.417249136216229</iyy>
            <iyz>-6.2494560922221609e-05</iyz>
            <izz>13.41012420152623</izz>
          </inertia>
        </inertial>
        <collision name='dummy_base_link_fixed_joint_lump__base_link_collision'>
          <pose>0 0 0 0 0 1.5700000000000001</pose>
          <geometry>
            <mesh>
              <scale>0.001 0.001 0.001</scale>
              <uri>file:///bmstu/ros2_ws/install/main/share/main/meshes/base_link.stl</uri>
            </mesh>
          </geometry>
          <surface>
            <contact>
              <ode/>
            </contact>
            <friction>
              <ode>
                <mu>0.20000000000000001</mu>
                <mu2>0.20000000000000001</mu2>
              </ode>
            </friction>
          </surface>
        </collision>
        <collision name='dummy_base_link_fixed_joint_lump__laser_frame_collision_1'>
          <pose>0.69999999999999996 0 0.40000000000000002 0 0 0</pose>
          <geometry>
            <cylinder>
              <length>0.040000000000000001</length>
              <radius>0.040000000000000001</radius>
            </cylinder>
          </geometry>
          <surface>
            <contact>
              <ode/>
            </contact>
            <friction>
              <ode/>
            </friction>
            <bounce/>
          </surface>
        </collision>
        <visual name='dummy_base_link_fixed_joint_lump__base_link_visual'>
          <pose>0 0 0 0 0 1.5700000000000001</pose>
          <geometry>
            <mesh>
              <scale>0.001 0.001 0.001</scale>
              <uri>file:///bmstu/ros2_ws/install/main/share/main/meshes/base_link.stl</uri>
            </mesh>
          </geometry>
          <material>
            <script>
              <name>Gazebo/Silver</name>
              <uri>file://media/materials/scripts/gazebo.material</uri>
            </script>
            <diffuse>0.5 0.5 0.5 1</diffuse>
            <ambient>0.5 0.5 0.5 1</ambient>
          </material>
        </visual>
        <visual name='dummy_base_link_fixed_joint_lump__cam_link_1_visual_1'>
          <pose>0.59999999999999998 0 0.5 0 0 0</pose>
          <geometry>
            <cylinder>
              <length>0.20000000000000001</length>
              <radius>0.01</radius>
            </cylinder>
          </geometry>
          <material>
            <diffuse>0.875 0.875 0.875 1</diffuse>
            <ambient>0.875 0.875 0.875 1</ambient>
          </material>
        </visual>
        <visual name='dummy_base_link_fixed_joint_lump__cam_1_visual_2'>
          <pose>0.59999999999999998 0 0.59999999999999998 0 0 0</pose>
          <geometry>
            <box>
              <size>0.029999999999999999 0.10000000000000001 0.029999999999999999</size>
            </box>
          </geometry>
          <material>
            <diffuse>0.875 0.875 0.875 1</diffuse>
            <ambient>0.875 0.875 0.875 1</ambient>
          </material>
        </visual>
        <visual name='dummy_base_link_fixed_joint_lump__laser_frame_visual_3'>
          <pose>0.69999999999999996 0 0.40000000000000002 0 0 0</pose>
          <geometry>
            <cylinder>
              <length>0.040000000000000001</length>
              <radius>0.040000000000000001</radius>
            </cylinder>
          </geometry>
        </visual>
        <self_collide>true</self_collide>
        <gravity>true</gravity>
        <sensor name='camera' type='camera'>
          <pose>0.59999999999999998 0 0.59999999999999998 0 0 0</pose>
          <topic>camera/image</topic>
          <update_rate>30</update_rate>
          <enable_metrics>false</enable_metrics>
          <camera name='camera'>
            <pose>0 0 0 0 0 0</pose>
            <horizontal_fov>1.8</horizontal_fov>
            <image>
              <width>640</width>
              <height>640</height>
              <format>RGB_INT8</format>
              <anti_aliasing>4</anti_aliasing>
            </image>
            <camera_info_topic>camera/camera_info</camera_info_topic>
            <trigger_topic></trigger_topic>
            <triggered>false</triggered>
            <clip>
              <near>0.10000000000000001</near>
              <far>20</far>
            </clip>
            <save enabled='false'>
              <path>__default__</path>
            </save>
            <visibility_mask>4294967295</visibility_mask>
            <noise>
              <type>none</type>
              <mean>0</mean>
              <stddev>0</stddev>
            </noise>
            <distortion>
              <k1>0</k1>
              <k2>0</k2>
              <k3>0</k3>
              <p1>0</p1>
              <p2>0</p2>
              <center>0.5 0.5</center>
            </distortion>
            <lens>
              <type>stereographic</type>
              <scale_to_hfov>true</scale_to_hfov>
              <cutoff_angle>1.5707963267948966</cutoff_angle>
              <env_texture_size>256</env_texture_size>
            </lens>
            <optical_frame_id></optical_frame_id>
          </camera>
        </sensor>
        <sensor name='depth_camera' type='depth_camera'>
          <pose>0.59999999999999998 0 0.59999999999999998 0 0 0</pose>
          <topic>depth_camera/image</topic>
          <update_rate>10</update_rate>
          <enable_metrics>false</enable_metrics>
          <camera name='depth_camera'>
            <pose>0 0 0 0 0 0</pose>
            <horizontal_fov>1.8</horizontal_fov>
            <image>
              <width>640</width>
              <height>640</height>
              <format>RGB_INT8</format>
              <anti_aliasing>4</anti_aliasing>
            </image>
            <camera_info_topic>depth_camera/camera_info</camera_info_topic>
            <trigger_topic></trigger_topic>
            <triggered>false</triggered>
            <clip>
              <near>0.10000000000000001</near>
              <far>20</far>
            </clip>
            <save enabled='false'>
              <path>__default__</path>
            </save>
            <visibility_mask>4294967295</visibility_mask>
            <noise>
              <type>none</type>
              <mean>0</mean>
              <stddev>0</stddev>
            </noise>
            <distortion>
              <k1>0</k1>
              <k2>0</k2>
              <k3>0</k3>
              <p1>0</p1>
              <p2>0</p2>
              <center>0.5 0.5</center>
            </distortion>
            <lens>
              <type>stereographic</type>
              <scale_to_hfov>true</scale_to_hfov>
              <cutoff_angle>1.5707963267948966</cutoff_angle>
              <env_texture_size>256</env_texture_size>
            </lens>
            <optical_frame_id></optical_frame_id>
          </camera>
        </sensor>
        <sensor name='laser' type='gpu_lidar'>
          <pose>0.69999999999999996 0 0.40000000000000002 0 0 0</pose>
          <topic>scan</topic>
          <update_rate>10</update_rate>
          <enable_metrics>false</enable_metrics>
          <lidar>
            <scan>
              <horizontal>
                <samples>360</samples>
                <resolution>1</resolution>
                <min_angle>-3.1400000000000001</min_angle>
                <max_angle>3.1400000000000001</max_angle>
              </horizontal>
              <vertical>
                <samples>1</samples>
                <min_angle>0</min_angle>
                <max_angle>0</max_angle>
                <resolution>1</resolution>
              </vertical>
            </scan>
            <range>
              <min>0.29999999999999999</min>
              <max>15</max>
              <resolution>0</resolution>
            </range>
            <noise>
              <type>none</type>
              <mean>0</mean>
              <stddev>0</stddev>
            </noise>
            <visibility_mask>4294967295</visibility_mask>
          </lidar>
        </sensor>
        <pose>0 0 0 0 0 0</pose>
        <enable_wind>false</enable_wind>
      </link>
      <joint name='blw_to_body' type='revolute'>
        <pose>-5.5511151231257827e-17 0 2.7755575615628914e-17 0 0 0</pose>
        <parent>dummy_base_link</parent>
        <child>bl_wheel_1</child>
        <axis>
          <xyz>-1 0 0</xyz>
          <limit>
            <lower>-inf</lower>
            <upper>inf</upper>
            <effort>inf</effort>
            <velocity>inf</velocity>
            <stiffness>100000000</stiffness>
            <dissipation>1</dissipation>
          </limit>
          <dynamics>
            <spring_reference>0</spring_reference>
            <spring_stiffness>0</spring_stiffness>
            <damping>0</damping>
            <friction>0</friction>
          </dynamics>
        </axis>
      </joint>
      <link name='bl_wheel_1'>
        <pose>-0.38895800000000003 0.35000000000000009 0.196191 -0.43029411762458614 5.5511151231257827e-17 -1.5699999999999996</pose>
        <inertial>
          <pose>0.055000000000000049 1.09885824439715e-07 -4.0437316886632319e-07 0 0 0</pose>
          <mass>11.601995917486709</mass>
          <inertia>
            <ixx>0.20941599999999999</ixx>
            <ixy>0</ixy>
            <ixz>0</ixz>
            <iyy>0.116407</iyy>
            <iyz>0</iyz>
            <izz>0.116407</izz>
          </inertia>
        </inertial>
        <collision name='bl_wheel_1_collision'>
          <pose>-0.45000000000000001 -0.38895800000000003 -0.196191 0 0 0</pose>
          <geometry>
            <mesh>
              <scale>0.001 0.001 0.001</scale>
              <uri>file:///bmstu/ros2_ws/install/main/share/main/meshes/bl_wheel_1.stl</uri>
            </mesh>
          </geometry>
          <surface>
            <contact>
              <ode/>
            </contact>
            <friction>
              <ode>
                <mu>0.001</mu>
                <mu2>0.001</mu2>
              </ode>
            </friction>
          </surface>
        </collision>
        <visual name='bl_wheel_1_visual'>
          <pose>-0.45000000000000001 -0.38895800000000003 -0.196191 0 0 0</pose>
          <geometry>
            <mesh>
              <scale>0.001 0.001 0.001</scale>
              <uri>file:///bmstu/ros2_ws/install/main/share/main/meshes/bl_wheel_1.stl</uri>
            </mesh>
          </geometry>
          <material>
            <diffuse>0.125 0.125 0.125 1</diffuse>
            <ambient>0.125 0.125 0.125 1</ambient>
          </material>
        </visual>
        <enable_wind>false</enable_wind>
      </link>
      <joint name='brw_to_body' type='revolute'>
        <pose>0 -1.1102230246251565e-16 2.7755575615628914e-17 0 0 0</pose>
        <parent>dummy_base_link</parent>
        <child>br_wheel_1</child>
        <axis>
          <xyz>-1 0 0</xyz>
          <limit>
            <lower>-inf</lower>
            <upper>inf</upper>
            <effort>inf</effort>
            <velocity>inf</velocity>
            <stiffness>100000000</stiffness>
            <dissipation>1</dissipation>
          </limit>
          <dynamics>
            <spring_reference>0</spring_reference>
            <spring_stiffness>0</spring_stiffness>
            <damping>0</damping>
            <friction>0</friction>
          </dynamics>
        </axis>
      </joint>
      <link name='br_wheel_1'>
        <pose>-0.38895800000000014 -0.35000000000000009 0.19619100000000006 0.43029411762123126 5.5511151231257827e-17 -1.5699999999999996</pose>
        <inertial>
          <pose>-0.055000000000000097 1.09885824439715e-07 -4.0437316886632319e-07 0 0 0</pose>
          <mass>11.601995917486709</mass>
          <inertia>
            <ixx>0.20941599999999999</ixx>
            <ixy>0</ixy>
            <ixz>0</ixz>
            <iyy>0.116407</iyy>
            <iyz>0</iyz>
            <izz>0.116407</izz>
          </inertia>
        </inertial>
        <collision name='br_wheel_1_collision'>
          <pose>0.45000000000000001 -0.38895800000000003 -0.196191 0 0 0</pose>
          <geometry>
            <mesh>
              <scale>0.001 0.001 0.001</scale>
              <uri>file:///bmstu/ros2_ws/install/main/share/main/meshes/br_wheel_1.stl</uri>
            </mesh>
          </geometry>
          <surface>
            <contact>
              <ode/>
            </contact>
            <friction>
              <ode>
                <mu>0.001</mu>
                <mu2>0.001</mu2>
              </ode>
            </friction>
          </surface>
        </collision>
        <visual name='br_wheel_1_visual'>
          <pose>0.45000000000000001 -0.38895800000000003 -0.196191 0 0 0</pose>
          <geometry>
            <mesh>
              <scale>0.001 0.001 0.001</scale>
              <uri>file:///bmstu/ros2_ws/install/main/share/main/meshes/br_wheel_1.stl</uri>
            </mesh>
          </geometry>
          <material>
            <diffuse>0.125 0.125 0.125 1</diffuse>
            <ambient>0.125 0.125 0.125 1</ambient>
          </material>
        </visual>
        <enable_wind>false</enable_wind>
      </link>
      <joint name='flw_to_body' type='revolute'>
        <pose>1.1102230246251565e-16 -1.1102230246251565e-16 2.7755575615628914e-17 0 0 0</pose>
        <parent>dummy_base_link</parent>
        <child>fl_wheel_1</child>
        <axis>
          <xyz>-1 0 0</xyz>
          <limit>
            <lower>-inf</lower>
            <upper>inf</upper>
            <effort>inf</effort>
            <velocity>inf</velocity>
            <stiffness>100000000</stiffness>
            <dissipation>1</dissipation>
          </limit>
          <dynamics>
            <spring_reference>0</spring_reference>
            <spring_stiffness>0</spring_stiffness>
            <damping>0</damping>
            <friction>0</friction>
          </dynamics>
        </axis>
      </joint>
      <link name='fl_wheel_1'>
        <pose>0.49104189012438604 0.35000000386736185 0.19619167553623276 -0.4302935393077929 -2.0815420193054379e-08 -1.570000000000068</pose>
        <inertial>
          <pose>0.055000000000000049 1.098858243286926e-07 -4.0437316894959002e-07 0 0 0</pose>
          <mass>11.601995917486709</mass>
          <inertia>
            <ixx>0.20941599999999999</ixx>
            <ixy>0</ixy>
            <ixz>0</ixz>
            <iyy>0.116407</iyy>
            <iyz>0</iyz>
            <izz>0.116407</izz>
          </inertia>
        </inertial>
        <collision name='fl_wheel_1_collision'>
          <pose>-0.45000000000000001 0.49104199999999998 -0.196191 0 0 0</pose>
          <geometry>
            <mesh>
              <scale>0.001 0.001 0.001</scale>
              <uri>file:///bmstu/ros2_ws/install/main/share/main/meshes/fl_wheel_1.stl</uri>
            </mesh>
          </geometry>
          <surface>
            <contact>
              <ode/>
            </contact>
            <friction>
              <ode>
                <mu>0.001</mu>
                <mu2>0.001</mu2>
              </ode>
            </friction>
          </surface>
        </collision>
        <visual name='fl_wheel_1_visual'>
          <pose>-0.45000000000000001 0.49104199999999998 -0.196191 0 0 0</pose>
          <geometry>
            <mesh>
              <scale>0.001 0.001 0.001</scale>
              <uri>file:///bmstu/ros2_ws/install/main/share/main/meshes/fl_wheel_1.stl</uri>
            </mesh>
          </geometry>
          <material>
            <diffuse>0.125 0.125 0.125 1</diffuse>
            <ambient>0.125 0.125 0.125 1</ambient>
          </material>
        </visual>
        <enable_wind>false</enable_wind>
      </link>
      <joint name='frw_to_body' type='revolute'>
        <pose>1.1102230246251565e-16 5.5511151231257827e-17 2.7755575615628914e-17 0 0 0</pose>
        <parent>dummy_base_link</parent>
        <child>fr_wheel_1</child>
        <axis>
          <xyz>-1 0 0</xyz>
          <limit>
            <lower>-inf</lower>
            <upper>inf</upper>
            <effort>inf</effort>
            <velocity>inf</velocity>
            <stiffness>100000000</stiffness>
            <dissipation>1</dissipation>
          </limit>
          <dynamics>
            <spring_reference>0</spring_reference>
            <spring_stiffness>0</spring_stiffness>
            <damping>0</damping>
            <friction>0</friction>
          </dynamics>
        </axis>
      </joint>
      <link name='fr_wheel_1'>
        <pose>0.49104193539158714 -0.34999999772593182 0.19619140560309684 0.4302944576702521 -1.2239751323583903e-08 -1.5700000000000234</pose>
        <inertial>
          <pose>-0.055000000000000097 1.098858243286926e-07 -4.0437316894959002e-07 0 0 0</pose>
          <mass>11.601995917486709</mass>
          <inertia>
            <ixx>0.20941599999999999</ixx>
            <ixy>0</ixy>
            <ixz>0</ixz>
            <iyy>0.116407</iyy>
            <iyz>0</iyz>
            <izz>0.116407</izz>
          </inertia>
        </inertial>
        <collision name='fr_wheel_1_collision'>
          <pose>0.45000000000000001 0.49104199999999998 -0.196191 0 0 0</pose>
          <geometry>
            <mesh>
              <scale>0.001 0.001 0.001</scale>
              <uri>file:///bmstu/ros2_ws/install/main/share/main/meshes/fr_wheel_1.stl</uri>
            </mesh>
          </geometry>
          <surface>
            <contact>
              <ode/>
            </contact>
            <friction>
              <ode>
                <mu>0.001</mu>
                <mu2>0.001</mu2>
              </ode>
            </friction>
          </surface>
        </collision>
        <visual name='fr_wheel_1_visual'>
          <pose>0.45000000000000001 0.49104199999999998 -0.196191 0 0 0</pose>
          <geometry>
            <mesh>
              <scale>0.001 0.001 0.001</scale>
              <uri>file:///bmstu/ros2_ws/install/main/share/main/meshes/fr_wheel_1.stl</uri>
            </mesh>
          </geometry>
          <material>
            <diffuse>0.125 0.125 0.125 1</diffuse>
            <ambient>0.125 0.125 0.125 1</ambient>
          </material>
        </visual>
        <enable_wind>false</enable_wind>
      </link>
      <joint name='mlw_to_body' type='revolute'>
        <pose>0 -5.5511151231257827e-17 2.7755575615628914e-17 0 0 0</pose>
        <parent>dummy_base_link</parent>
        <child>ml_wheel_1</child>
        <axis>
          <xyz>-1 0 0</xyz>
          <limit>
            <lower>-inf</lower>
            <upper>inf</upper>
            <effort>inf</effort>
            <velocity>inf</velocity>
            <stiffness>100000000</stiffness>
            <dissipation>1</dissipation>
          </limit>
          <dynamics>
            <spring_reference>0</spring_reference>
            <spring_stiffness>0</spring_stiffness>
            <damping>0</damping>
            <friction>0</friction>
          </dynamics>
        </axis>
      </joint>
      <link name='ml_wheel_1'>
        <pose>0.051042000000000254 0.35000000000000031 0.196191 -0.43029411762600256 1.9428902930940239e-16 -1.5699999999999998</pose>
        <inertial>
          <pose>0.055000000000000049 1.0988582444665381e-07 -4.0437316886632319e-07 0 0 0</pose>
          <mass>11.601995917486709</mass>
          <inertia>
            <ixx>0.20941599999999999</ixx>
            <ixy>0</ixy>
            <ixz>0</ixz>
            <iyy>0.116407</iyy>
            <iyz>0</iyz>
            <izz>0.116407</izz>
          </inertia>
        </inertial>
        <collision name='ml_wheel_1_collision'>
          <pose>-0.45000000000000001 0.051041999999999997 -0.196191 0 0 0</pose>
          <geometry>
            <mesh>
              <scale>0.001 0.001 0.001</scale>
              <uri>file:///bmstu/ros2_ws/install/main/share/main/meshes/ml_wheel_1.stl</uri>
            </mesh>
          </geometry>
        </collision>
        <visual name='ml_wheel_1_visual'>
          <pose>-0.45000000000000001 0.051041999999999997 -0.196191 0 0 0</pose>
          <geometry>
            <mesh>
              <scale>0.001 0.001 0.001</scale>
              <uri>file:///bmstu/ros2_ws/install/main/share/main/meshes/ml_wheel_1.stl</uri>
            </mesh>
          </geometry>
          <material>
            <diffuse>0.125 0.125 0.125 1</diffuse>
            <ambient>0.125 0.125 0.125 1</ambient>
          </material>
        </visual>
        <enable_wind>false</enable_wind>
      </link>
      <joint name='mrw_to_body' type='revolute'>
        <pose>5.5511151231257827e-17 0 2.7755575615628914e-17 0 0 0</pose>
        <parent>dummy_base_link</parent>
        <child>mr_wheel_1</child>
        <axis>
          <xyz>-1 0 0</xyz>
          <limit>
            <lower>-inf</lower>
            <upper>inf</upper>
            <effort>inf</effort>
            <velocity>inf</velocity>
            <stiffness>100000000</stiffness>
            <dissipation>1</dissipation>
          </limit>
          <dynamics>
            <spring_reference>0</spring_reference>
            <spring_stiffness>0</spring_stiffness>
            <damping>0</damping>
            <friction>0</friction>
          </dynamics>
        </axis>
      </joint>
      <link name='mr_wheel_1'>
        <pose>0.051041871683079609 -0.3499999954835179 0.19619150839571853 0.43029479298640499 -2.430905604589029e-08 -1.57000000000011</pose>
        <inertial>
          <pose>-0.055000000000000097 1.0988582444665381e-07 -4.0437316886632319e-07 0 0 0</pose>
          <mass>11.601995917486709</mass>
          <inertia>
            <ixx>0.20941599999999999</ixx>
            <ixy>0</ixy>
            <ixz>0</ixz>
            <iyy>0.116407</iyy>
            <iyz>0</iyz>
            <izz>0.116407</izz>
          </inertia>
        </inertial>
        <collision name='mr_wheel_1_collision'>
          <pose>0.45000000000000001 0.051041999999999997 -0.196191 0 0 0</pose>
          <geometry>
            <mesh>
              <scale>0.001 0.001 0.001</scale>
              <uri>file:///bmstu/ros2_ws/install/main/share/main/meshes/mr_wheel_1.stl</uri>
            </mesh>
          </geometry>
        </collision>
        <visual name='mr_wheel_1_visual'>
          <pose>0.45000000000000001 0.051041999999999997 -0.196191 0 0 0</pose>
          <geometry>
            <mesh>
              <scale>0.001 0.001 0.001</scale>
              <uri>file:///bmstu/ros2_ws/install/main/share/main/meshes/mr_wheel_1.stl</uri>
            </mesh>
          </geometry>
          <material>
            <diffuse>0.125 0.125 0.125 1</diffuse>
            <ambient>0.125 0.125 0.125 1</ambient>
          </material>
        </visual>
        <enable_wind>false</enable_wind>
      </link>
      <plugin name='gz::sim::systems::JointStatePublisher' filename='gz-sim-joint-state-publisher-system'>
        <topic>joint_states</topic>
      </plugin>
      <plugin name='gz::sim::systems::DiffDrive' filename='gz-sim-diff-drive-system'>
        <left_joint>blw_to_body</left_joint>
        <left_joint>mlw_to_body</left_joint>
        <left_joint>flw_to_body</left_joint>
        <right_joint>brw_to_body</right_joint>
        <right_joint>mrw_to_body</right_joint>
        <right_joint>frw_to_body</right_joint>
        <wheel_separation>1.1</wheel_separation>
        <wheel_radius>0.17</wheel_radius>
        <topic>cmd_vel</topic>
        <frame_id>odom</frame_id>
        <child_frame_id>dummy_base_link</child_frame_id>
        <odom_topic>odom</odom_topic>
        <odom_publisher_frequency>30</odom_publisher_frequency>
        <tf_topic>/tf</tf_topic>
      </plugin>
      <frame name='cam_to_camlink' attached_to='cam_link_1'>
        <pose>0 0 0.10000000000000001 0 0 0</pose>
      </frame>
      <frame name='cam_1' attached_to='cam_to_camlink'>
        <pose>0 0 0 0 0 0</pose>
      </frame>
      <frame name='camlink_to_body' attached_to='base_link'>
        <pose>0.59999999999999998 0 0.5 0 0 0</pose>
      </frame>
      <frame name='cam_link_1' attached_to='camlink_to_body'>
        <pose>0 0 0 0 0 0</pose>
      </frame>
      <frame name='laser_joint' attached_to='base_link'>
        <pose>0.69999999999999996 0 0.40000000000000002 0 0 0</pose>
      </frame>
      <frame name='laser_frame' attached_to='laser_joint'>
        <pose>0 0 0 0 0 0</pose>
      </frame>
      <frame name='dummy' attached_to='dummy_base_link'>
        <pose>0 0 0 0 0 0</pose>
      </frame>
      <frame name='base_link' attached_to='dummy'>
        <pose>0 0 0 0 0 0</pose>
      </frame>
      <pose>1.0227439404557521 0.9985723023205475 -0.0061963681269277615 1.4808394066723518e-07 8.3001635698020477e-07 -0.022843718470925149</pose>
      <static>false</static>
      <self_collide>false</self_collide>
    </model>
    <model name='box'>
      <pose>4.256751826940862 1.0016881556735806 0.49999999990199806 6.2287739151293738e-22 9.3279666454713669e-22 -3.6315533669320137e-22</pose>
      <link name='box_link'>
        <inertial>
          <inertia>
            <ixx>0.16666</ixx>
            <ixy>0</ixy>
            <ixz>0</ixz>
            <iyy>0.16666</iyy>
            <iyz>0</iyz>
            <izz>0.16666</izz>
          </inertia>
          <mass>1</mass>
          <pose>0 0 0 0 0 0</pose>
        </inertial>
        <collision name='box_collision'>
          <geometry>
            <box>
              <size>1 1 1</size>
            </box>
          </geometry>
          <surface>
            <friction>
              <ode/>
            </friction>
            <bounce/>
            <contact/>
          </surface>
        </collision>
        <visual name='box_visual'>
          <geometry>
            <box>
              <size>1 1 1</size>
            </box>
          </geometry>
          <material>
            <ambient>0.300000012 0.300000012 0.300000012 1</ambient>
            <diffuse>0.699999988 0.699999988 0.699999988 1</diffuse>
            <specular>1 1 1 1</specular>
          </material>
        </visual>
        <pose>0 0 0 0 0 0</pose>
        <enable_wind>false</enable_wind>
      </link>
      <static>false</static>
      <self_collide>false</self_collide>
    </model>
    <model name='box_0'>
      <pose>7.3354242387478852 1.1793236354167376 0.49999999990199806 6.2287739151293738e-22 9.3279666454713669e-22 -3.6315533669320137e-22</pose>
      <link name='box_link'>
        <inertial>
          <inertia>
            <ixx>0.16666</ixx>
            <ixy>0</ixy>
            <ixz>0</ixz>
            <iyy>0.16666</iyy>
            <iyz>0</iyz>
            <izz>0.16666</izz>
          </inertia>
          <mass>1</mass>
          <pose>0 0 0 0 0 0</pose>
        </inertial>
        <collision name='box_collision'>
          <geometry>
            <box>
              <size>1 1 1</size>
            </box>
          </geometry>
          <surface>
            <friction>
              <ode/>
            </friction>
            <bounce/>
            <contact/>
          </surface>
        </collision>
        <visual name='box_visual'>
          <geometry>
            <box>
              <size>1 1 1</size>
            </box>
          </geometry>
          <material>
            <ambient>0.300000012 0.300000012 0.300000012 1</ambient>
            <diffuse>0.699999988 0.699999988 0.699999988 1</diffuse>
            <specular>1 1 1 1</specular>
          </material>
        </visual>
        <pose>0 0 0 0 0 0</pose>
        <enable_wind>false</enable_wind>
      </link>
      <static>false</static>
      <self_collide>false</self_collide>
    </model>
    <model name='capsule'>
      <pose>3.7135111676159376 2.3350288114413038 0.499999999902001 0 0 0</pose>
      <link name='capsule_link'>
        <inertial>
          <inertia>
            <ixx>0.074153999999999998</ixx>
            <ixy>0</ixy>
            <ixz>0</ixz>
            <iyy>0.074153999999999998</iyy>
            <iyz>0</iyz>
            <izz>0.018769000000000001</izz>
          </inertia>
          <mass>1</mass>
          <pose>0 0 0 0 0 0</pose>
        </inertial>
        <collision name='capsule_collision'>
          <geometry>
            <capsule>
              <radius>0.20000000000000001</radius>
              <length>0.59999999999999998</length>
            </capsule>
          </geometry>
          <surface>
            <friction>
              <ode/>
            </friction>
            <bounce/>
            <contact/>
          </surface>
        </collision>
        <visual name='capsule_visual'>
          <geometry>
            <capsule>
              <radius>0.20000000000000001</radius>
              <length>0.59999999999999998</length>
            </capsule>
          </geometry>
          <material>
            <ambient>0.300000012 0.300000012 0.300000012 1</ambient>
            <diffuse>0.699999988 0.699999988 0.699999988 1</diffuse>
            <specular>1 1 1 1</specular>
          </material>
        </visual>
        <pose>0 0 0 0 0 0</pose>
        <enable_wind>false</enable_wind>
      </link>
      <static>false</static>
      <self_collide>false</self_collide>
    </model>
    <light name='sun' type='directional'>
      <pose>0 0 10 0 0 0</pose>
      <cast_shadows>true</cast_shadows>
      <intensity>1</intensity>
      <direction>-0.5 0.10000000000000001 -0.90000000000000002</direction>
      <diffuse>0.800000012 0.800000012 0.800000012 1</diffuse>
      <specular>0.200000003 0.200000003 0.200000003 1</specular>
      <attenuation>
        <range>1000</range>
        <linear>0.01</linear>
        <constant>0.90000000000000002</constant>
        <quadratic>0.001</quadratic>
      </attenuation>
      <spot>
        <inner_angle>0</inner_angle>
        <outer_angle>0</outer_angle>
        <falloff>0</falloff>
      </spot>
    </light>
  </world>
</sdf>
